<?xml version='1.0' encoding='UTF-8'?>
<mujoco model="ur3">
  <compiler angle="radian" meshdir="../meshes/ur3/collision/"/>

  <asset>
    <mesh name="base" content_type="model/stl" file="base.stl"/>
    <mesh name="shoulder" content_type="model/stl" file="shoulder.stl"/>
    <mesh name="upperarm" content_type="model/stl" file="upperarm.stl"/>
    <mesh name="forearm" content_type="model/stl" file="forearm.stl"/>
    <mesh name="wrist1" content_type="model/stl" file="wrist1.stl"/>
    <mesh name="wrist2" content_type="model/stl" file="wrist2.stl"/>
    <mesh name="wrist3" content_type="model/stl" file="wrist3.stl"/>
  </asset>

  <worldbody>
    <body name="base_link">
      <inertial pos="0 0 0" quat="0.5 0.5 -0.5 0.5" mass="2" diaginertia="0.005625 0.00305317 0.00305317"/>
      <geom type="mesh" rgba="0.7 0.7 0.7 1" mesh="base"/>
      <body name="shoulder_link" pos="0 0 0.1519">
        <inertial pos="0.000000e+00 0.000000e+00 0.000000e+00" mass="3.950000e+00" diaginertia="1.493111e-02 1.493111e-02 1.268527e-02"/>
        <joint name="shoulder_pan_joint" pos="0 0 0" axis="0 0 1" range="-6.28319 6.28319" actuatorfrcrange="-330 330" armature="8.000000e+00"/>
        <geom type="mesh" rgba="0.7 0.7 0.7 1" mesh="shoulder"/>
        <body name="upper_arm_link" pos="0 0.1198 0" quat="0.707107 0 0.707107 0">
          <inertial pos="0.000000e+00 0.000000e+00 1.218250e-01" mass="5.370000e+00" diaginertia="2.856645e-02 2.856645e-02 1.667903e-02"/>
          <joint name="shoulder_lift_joint" pos="0 0 0" axis="0 1 0" range="-6.28319 6.28319" actuatorfrcrange="-330 330" armature="8.000000e+00"/>
          <geom type="mesh" rgba="0.7 0.7 0.7 1" mesh="upperarm"/>
          <body name="forearm_link" pos="0 -0.0925 0.24365">
            <inertial pos="0.000000e+00 0.000000e+00 1.066250e-01" mass="3.610000e+00" diaginertia="1.388934e-02 1.388934e-02 1.103653e-02"/>
            <joint name="elbow_joint" pos="0 0 0" axis="0 1 0" range="-3.14159 3.14159" actuatorfrcrange="-150 150" armature="8.000000e+00"/>
            <geom type="mesh" rgba="0.7 0.7 0.7 1" mesh="forearm"/>
            <body name="wrist_1_link" pos="0 0 0.21325" quat="0.707107 0 0.707107 0">
              <inertial pos="0.000000e+00 0.000000e+00 0.000000e+00" quat="0.5 0.5 -0.5 0.5" mass="2.500000e+00" diaginertia="5.013292e-03 4.848292e-03 4.200250e-03"/>
              <joint name="wrist_1_joint" pos="0 0 0" axis="0 1 0" range="-6.28319 6.28319" actuatorfrcrange="-54 54" armature="9.100000e-01"/>
              <geom type="mesh" rgba="0.7 0.7 0.7 1" mesh="wrist1"/>
              <body name="wrist_2_link" pos="0 0.08505 0">
                <inertial pos="0.000000e+00 0.000000e+00 0.000000e+00" quat="0.5 0.5 -0.5 0.5" mass="5.500000e+00" diaginertia="1.115229e-02 1.098729e-02 1.011375e-02"/>
                <joint name="wrist_2_joint" pos="0 0 0" axis="0 0 1" range="-6.28319 6.28319" actuatorfrcrange="-54 54" armature="2.200000e+00"/>
                <geom type="mesh" rgba="0.7 0.7 0.7 1" mesh="wrist2"/>
                <body name="wrist_3_link" pos="0 0 0.08535">
                  <inertial pos="0.000000e+00 0.000000e+00 0.000000e+00" quat="0.5 0.5 -0.5 0.5" mass="2.200000e+00" diaginertia="3.822042e-03 3.749854e-03 3.091187e-03"/>
                  <joint name="wrist_3_joint" pos="0 0 0" axis="0 1 0" range="-6.28319 6.28319" actuatorfrcrange="-54 54" armature="9.100000e-01"/>
                  <geom type="mesh" rgba="0.7 0.7 0.7 1" mesh="wrist3"/>
                  <body name="ee_link" pos="0 0.0819 0" quat="0.707107 0 0 0.707107">
                    <geom size="0.005 0.005 0.005" pos="-0.01 0 0" type="box"/>
                  </body>
                  <body name="tool0" pos="0 0.0819 0" quat="0.707107 -0.707107 0 0"/>
                </body>
              </body>
            </body>
          </body>
        </body>
      </body>
      <body name="base" quat="0 0 0 -1"/>
    </body>
  </worldbody>
<actuator><general name="shoulder_pan_joint_motor_SHA32A-101" joint="shoulder_pan_joint" gear="101.0" ctrlrange="-4.287129 4.287129"/><general name="shoulder_lift_joint_motor_SHA32A-101" joint="shoulder_lift_joint" gear="101.0" ctrlrange="-4.287129 4.287129"/><general name="elbow_joint_motor_SHA32A-101" joint="elbow_joint" gear="101.0" ctrlrange="-4.287129 4.287129"/><general name="wrist_1_joint_motor_SHA20A-101" joint="wrist_1_joint" gear="101.0" ctrlrange="-1.059406 1.059406"/><general name="wrist_2_joint_motor_SHA25A-101" joint="wrist_2_joint" gear="101.0" ctrlrange="-2.019802 2.019802"/><general name="wrist_3_joint_motor_SHA20A-101" joint="wrist_3_joint" gear="101.0" ctrlrange="-1.059406 1.059406"/></actuator></mujoco>
